INFO:     Started server process [28776]
INFO:     Waiting for application startup.
StreamableHTTP session manager started
INFO:     Application startup complete.
INFO:     Uvicorn running on http://localhost:6969 (Press CTRL+C to quit)
Created new transport with session ID: b273f2d213224db6bf9aec81ab082015
INFO:     ::1:56356 - "POST /mcp HTTP/1.1" 200 OK
INFO:     ::1:56357 - "POST /mcp HTTP/1.1" 202 Accepted
INFO:     ::1:56358 - "GET /mcp HTTP/1.1" 200 OK
INFO:     ::1:56359 - "POST /mcp HTTP/1.1" 200 OK
Processing request of type ListToolsRequest
INFO:     ::1:56375 - "POST /mcp HTTP/1.1" 200 OK
Processing request of type ListToolsRequest
INFO:     ::1:56376 - "POST /mcp HTTP/1.1" 200 OK
Processing request of type CallToolRequest
INFO:     ::1:56377 - "POST /mcp HTTP/1.1" 200 OK
Processing request of type ListToolsRequest
INFO:     ::1:56379 - "POST /mcp HTTP/1.1" 200 OK
Processing request of type ListToolsRequest
Exception in callback _ProactorBasePipeTransport._call_connection_lost(None)
handle: <Handle _ProactorBasePipeTransport._call_connection_lost(None)>
Traceback (most recent call last):
  File "C:\Users\User\AppData\Roaming\uv\python\cpython-3.11.13-windows-x86_64-none\Lib\asyncio\events.py", line 84, in _run
    self._context.run(self._callback, *self._args)
  File "C:\Users\User\AppData\Roaming\uv\python\cpython-3.11.13-windows-x86_64-none\Lib\asyncio\proactor_events.py", line 165, in _call_connection_lost
    self._sock.shutdown(socket.SHUT_RDWR)
ConnectionResetError: [WinError 10054] An existing connection was forcibly closed by the remote host
INFO:     ::1:56380 - "POST /mcp HTTP/1.1" 200 OK
Processing request of type CallToolRequest
Exception in callback _ProactorBasePipeTransport._call_connection_lost(None)
handle: <Handle _ProactorBasePipeTransport._call_connection_lost(None)>
Traceback (most recent call last):
  File "C:\Users\User\AppData\Roaming\uv\python\cpython-3.11.13-windows-x86_64-none\Lib\asyncio\events.py", line 84, in _run
    self._context.run(self._callback, *self._args)
  File "C:\Users\User\AppData\Roaming\uv\python\cpython-3.11.13-windows-x86_64-none\Lib\asyncio\proactor_events.py", line 165, in _call_connection_lost
    self._sock.shutdown(socket.SHUT_RDWR)
ConnectionResetError: [WinError 10054] An existing connection was forcibly closed by the remote host
INFO:     ::1:56392 - "POST /mcp HTTP/1.1" 200 OK
Processing request of type ListToolsRequest
INFO:     ::1:56397 - "POST /mcp HTTP/1.1" 200 OK
Processing request of type ListToolsRequest
INFO:     ::1:57969 - "POST /mcp HTTP/1.1" 200 OK
Processing request of type ListToolsRequest
Exception in callback _ProactorBasePipeTransport._call_connection_lost(None)
handle: <Handle _ProactorBasePipeTransport._call_connection_lost(None)>
Traceback (most recent call last):
  File "C:\Users\User\AppData\Roaming\uv\python\cpython-3.11.13-windows-x86_64-none\Lib\asyncio\events.py", line 84, in _run
    self._context.run(self._callback, *self._args)
  File "C:\Users\User\AppData\Roaming\uv\python\cpython-3.11.13-windows-x86_64-none\Lib\asyncio\proactor_events.py", line 165, in _call_connection_lost
    self._sock.shutdown(socket.SHUT_RDWR)
ConnectionResetError: [WinError 10054] An existing connection was forcibly closed by the remote host
INFO:     ::1:57974 - "POST /mcp HTTP/1.1" 200 OK
Processing request of type ListToolsRequest
Created new transport with session ID: 3101ebc344984dcf817752660aa1c646
INFO:     ::1:57975 - "POST /mcp HTTP/1.1" 200 OK
INFO:     ::1:57976 - "POST /mcp HTTP/1.1" 202 Accepted
INFO:     ::1:57977 - "GET /mcp HTTP/1.1" 200 OK
INFO:     ::1:57978 - "POST /mcp HTTP/1.1" 200 OK
Processing request of type ListToolsRequest
INFO:     ::1:57985 - "POST /mcp HTTP/1.1" 200 OK
Processing request of type ListToolsRequest
INFO:     ::1:57986 - "POST /mcp HTTP/1.1" 200 OK
Processing request of type CallToolRequest
INFO:     ::1:57993 - "POST /mcp HTTP/1.1" 200 OK
Processing request of type ListToolsRequest
INFO:     ::1:57361 - "POST /mcp HTTP/1.1" 200 OK
Processing request of type ListToolsRequest
INFO:     ::1:57254 - "POST /mcp HTTP/1.1" 200 OK
Processing request of type ListToolsRequest
INFO:     ::1:57266 - "POST /mcp HTTP/1.1" 200 OK
Processing request of type ListToolsRequest
Created new transport with session ID: 638e3b1cb62f472eb9621034108bb645
INFO:     ::1:57267 - "POST /mcp HTTP/1.1" 200 OK
INFO:     ::1:57268 - "POST /mcp HTTP/1.1" 202 Accepted
INFO:     ::1:57269 - "GET /mcp HTTP/1.1" 200 OK
INFO:     ::1:57270 - "POST /mcp HTTP/1.1" 200 OK
Processing request of type ListToolsRequest
INFO:     ::1:57279 - "POST /mcp HTTP/1.1" 200 OK
Processing request of type ListToolsRequest
Exception in callback _ProactorBasePipeTransport._call_connection_lost(None)
handle: <Handle _ProactorBasePipeTransport._call_connection_lost(None)>
Traceback (most recent call last):
  File "C:\Users\User\AppData\Roaming\uv\python\cpython-3.11.13-windows-x86_64-none\Lib\asyncio\events.py", line 84, in _run
    self._context.run(self._callback, *self._args)
  File "C:\Users\User\AppData\Roaming\uv\python\cpython-3.11.13-windows-x86_64-none\Lib\asyncio\proactor_events.py", line 165, in _call_connection_lost
    self._sock.shutdown(socket.SHUT_RDWR)
ConnectionResetError: [WinError 10054] An existing connection was forcibly closed by the remote host
INFO:     ::1:57280 - "POST /mcp HTTP/1.1" 200 OK
Processing request of type CallToolRequest
Exception in callback _ProactorBasePipeTransport._call_connection_lost(None)
handle: <Handle _ProactorBasePipeTransport._call_connection_lost(None)>
Traceback (most recent call last):
  File "C:\Users\User\AppData\Roaming\uv\python\cpython-3.11.13-windows-x86_64-none\Lib\asyncio\events.py", line 84, in _run
    self._context.run(self._callback, *self._args)
  File "C:\Users\User\AppData\Roaming\uv\python\cpython-3.11.13-windows-x86_64-none\Lib\asyncio\proactor_events.py", line 165, in _call_connection_lost
    self._sock.shutdown(socket.SHUT_RDWR)
ConnectionResetError: [WinError 10054] An existing connection was forcibly closed by the remote host
extracting....
done
INFO:     ::1:55703 - "POST /mcp HTTP/1.1" 200 OK
Processing request of type ListToolsRequest
Exception in callback _ProactorBasePipeTransport._call_connection_lost(None)
handle: <Handle _ProactorBasePipeTransport._call_connection_lost(None)>
Traceback (most recent call last):
  File "C:\Users\User\AppData\Roaming\uv\python\cpython-3.11.13-windows-x86_64-none\Lib\asyncio\events.py", line 84, in _run
    self._context.run(self._callback, *self._args)
  File "C:\Users\User\AppData\Roaming\uv\python\cpython-3.11.13-windows-x86_64-none\Lib\asyncio\proactor_events.py", line 165, in _call_connection_lost
    self._sock.shutdown(socket.SHUT_RDWR)
ConnectionResetError: [WinError 10054] An existing connection was forcibly closed by the remote host
INFO:     ::1:61388 - "POST /mcp HTTP/1.1" 200 OK
Processing request of type ListToolsRequest
INFO:     ::1:61389 - "POST /mcp HTTP/1.1" 200 OK
Processing request of type CallToolRequest
INFO:     ::1:61390 - "POST /mcp HTTP/1.1" 200 OK
Processing request of type ListToolsRequest
Exception in callback _ProactorBasePipeTransport._call_connection_lost(None)
handle: <Handle _ProactorBasePipeTransport._call_connection_lost(None)>
Traceback (most recent call last):
  File "C:\Users\User\AppData\Roaming\uv\python\cpython-3.11.13-windows-x86_64-none\Lib\asyncio\events.py", line 84, in _run
    self._context.run(self._callback, *self._args)
  File "C:\Users\User\AppData\Roaming\uv\python\cpython-3.11.13-windows-x86_64-none\Lib\asyncio\proactor_events.py", line 165, in _call_connection_lost
    self._sock.shutdown(socket.SHUT_RDWR)
ConnectionResetError: [WinError 10054] An existing connection was forcibly closed by the remote host
INFO:     ::1:61394 - "POST /mcp HTTP/1.1" 200 OK
Processing request of type ListToolsRequest
INFO:     ::1:61395 - "POST /mcp HTTP/1.1" 200 OK
Processing request of type CallToolRequest
Exception in callback _ProactorBasePipeTransport._call_connection_lost(None)
handle: <Handle _ProactorBasePipeTransport._call_connection_lost(None)>
Traceback (most recent call last):
  File "C:\Users\User\AppData\Roaming\uv\python\cpython-3.11.13-windows-x86_64-none\Lib\asyncio\events.py", line 84, in _run
    self._context.run(self._callback, *self._args)
  File "C:\Users\User\AppData\Roaming\uv\python\cpython-3.11.13-windows-x86_64-none\Lib\asyncio\proactor_events.py", line 165, in _call_connection_lost
    self._sock.shutdown(socket.SHUT_RDWR)
ConnectionResetError: [WinError 10054] An existing connection was forcibly closed by the remote host
extracting....
done
INFO:     ::1:58482 - "POST /mcp HTTP/1.1" 200 OK
Processing request of type ListToolsRequest
INFO:     ::1:64423 - "POST /mcp HTTP/1.1" 200 OK
Processing request of type ListToolsRequest
Exception in callback _ProactorBasePipeTransport._call_connection_lost(None)
handle: <Handle _ProactorBasePipeTransport._call_connection_lost(None)>
Traceback (most recent call last):
  File "C:\Users\User\AppData\Roaming\uv\python\cpython-3.11.13-windows-x86_64-none\Lib\asyncio\events.py", line 84, in _run
    self._context.run(self._callback, *self._args)
  File "C:\Users\User\AppData\Roaming\uv\python\cpython-3.11.13-windows-x86_64-none\Lib\asyncio\proactor_events.py", line 165, in _call_connection_lost
    self._sock.shutdown(socket.SHUT_RDWR)
ConnectionResetError: [WinError 10054] An existing connection was forcibly closed by the remote host
INFO:     ::1:64424 - "POST /mcp HTTP/1.1" 200 OK
Processing request of type CallToolRequest
Exception in callback _ProactorBasePipeTransport._call_connection_lost(None)
handle: <Handle _ProactorBasePipeTransport._call_connection_lost(None)>
Traceback (most recent call last):
  File "C:\Users\User\AppData\Roaming\uv\python\cpython-3.11.13-windows-x86_64-none\Lib\asyncio\events.py", line 84, in _run
    self._context.run(self._callback, *self._args)
  File "C:\Users\User\AppData\Roaming\uv\python\cpython-3.11.13-windows-x86_64-none\Lib\asyncio\proactor_events.py", line 165, in _call_connection_lost
    self._sock.shutdown(socket.SHUT_RDWR)
ConnectionResetError: [WinError 10054] An existing connection was forcibly closed by the remote host
extracting....
done
INFO:     ::1:59267 - "POST /mcp HTTP/1.1" 200 OK
Processing request of type ListToolsRequest
INFO:     ::1:51584 - "POST /mcp HTTP/1.1" 200 OK
Processing request of type ListToolsRequest
Exception in callback _ProactorBasePipeTransport._call_connection_lost(None)
handle: <Handle _ProactorBasePipeTransport._call_connection_lost(None)>
Traceback (most recent call last):
  File "C:\Users\User\AppData\Roaming\uv\python\cpython-3.11.13-windows-x86_64-none\Lib\asyncio\events.py", line 84, in _run
    self._context.run(self._callback, *self._args)
  File "C:\Users\User\AppData\Roaming\uv\python\cpython-3.11.13-windows-x86_64-none\Lib\asyncio\proactor_events.py", line 165, in _call_connection_lost
    self._sock.shutdown(socket.SHUT_RDWR)
ConnectionResetError: [WinError 10054] An existing connection was forcibly closed by the remote host
INFO:     ::1:62338 - "POST /mcp HTTP/1.1" 200 OK
Processing request of type ListToolsRequest
INFO:     ::1:62349 - "POST /mcp HTTP/1.1" 200 OK
Processing request of type ListToolsRequest
INFO:     ::1:62350 - "POST /mcp HTTP/1.1" 200 OK
Processing request of type CallToolRequest
Exception in callback _ProactorBasePipeTransport._call_connection_lost(None)
handle: <Handle _ProactorBasePipeTransport._call_connection_lost(None)>
Traceback (most recent call last):
  File "C:\Users\User\AppData\Roaming\uv\python\cpython-3.11.13-windows-x86_64-none\Lib\asyncio\events.py", line 84, in _run
    self._context.run(self._callback, *self._args)
  File "C:\Users\User\AppData\Roaming\uv\python\cpython-3.11.13-windows-x86_64-none\Lib\asyncio\proactor_events.py", line 165, in _call_connection_lost
    self._sock.shutdown(socket.SHUT_RDWR)
ConnectionResetError: [WinError 10054] An existing connection was forcibly closed by the remote host
extracting....
done
INFO:     ::1:54275 - "POST /mcp HTTP/1.1" 200 OK
Processing request of type ListToolsRequest
INFO:     ::1:53260 - "POST /mcp HTTP/1.1" 200 OK
Processing request of type ListToolsRequest
Exception in callback _ProactorBasePipeTransport._call_connection_lost(None)
handle: <Handle _ProactorBasePipeTransport._call_connection_lost(None)>
Traceback (most recent call last):
  File "C:\Users\User\AppData\Roaming\uv\python\cpython-3.11.13-windows-x86_64-none\Lib\asyncio\events.py", line 84, in _run
    self._context.run(self._callback, *self._args)
  File "C:\Users\User\AppData\Roaming\uv\python\cpython-3.11.13-windows-x86_64-none\Lib\asyncio\proactor_events.py", line 165, in _call_connection_lost
    self._sock.shutdown(socket.SHUT_RDWR)
ConnectionResetError: [WinError 10054] An existing connection was forcibly closed by the remote host
INFO:     Shutting down
INFO:     Waiting for connections to close. (CTRL+C to force quit)
INFO:     Finished server process [28776]
StreamableHTTP session manager shutting down
ERROR:    Exception in ASGI application
Traceback (most recent call last):
  File "C:\Users\User\Desktop\genai-desktop-app\agent\.venv\Lib\site-packages\anyio\_backends\_asyncio.py", line 2325, in run
    return runner.run(wrapper())
           ^^^^^^^^^^^^^^^^^^^^^
  File "C:\Users\User\AppData\Roaming\uv\python\cpython-3.11.13-windows-x86_64-none\Lib\asyncio\runners.py", line 118, in run
    return self._loop.run_until_complete(task)
           ^^^^^^^^^^^^^^^^^^^^^^^^^^^^^^^^^^^
  File "C:\Users\User\AppData\Roaming\uv\python\cpython-3.11.13-windows-x86_64-none\Lib\asyncio\base_events.py", line 641, in run_until_complete
    self.run_forever()
  File "C:\Users\User\AppData\Roaming\uv\python\cpython-3.11.13-windows-x86_64-none\Lib\asyncio\windows_events.py", line 321, in run_forever
    super().run_forever()
  File "C:\Users\User\AppData\Roaming\uv\python\cpython-3.11.13-windows-x86_64-none\Lib\asyncio\base_events.py", line 608, in run_forever
    self._run_once()
  File "C:\Users\User\AppData\Roaming\uv\python\cpython-3.11.13-windows-x86_64-none\Lib\asyncio\base_events.py", line 1936, in _run_once
    handle._run()
  File "C:\Users\User\AppData\Roaming\uv\python\cpython-3.11.13-windows-x86_64-none\Lib\asyncio\events.py", line 84, in _run
    self._context.run(self._callback, *self._args)
  File "C:\Users\User\Desktop\genai-desktop-app\agent\.venv\Lib\site-packages\anyio\_backends\_asyncio.py", line 2313, in wrapper
    return await func(*args)
           ^^^^^^^^^^^^^^^^^
  File "C:\Users\User\Desktop\genai-desktop-app\agent\.venv\Lib\site-packages\mcp\server\fastmcp\server.py", line 741, in run_streamable_http_async
    await server.serve()
  File "C:\Users\User\Desktop\genai-desktop-app\agent\.venv\Lib\site-packages\uvicorn\server.py", line 70, in serve
    with self.capture_signals():
  File "C:\Users\User\AppData\Roaming\uv\python\cpython-3.11.13-windows-x86_64-none\Lib\contextlib.py", line 144, in __exit__
    next(self.gen)
  File "C:\Users\User\Desktop\genai-desktop-app\agent\.venv\Lib\site-packages\uvicorn\server.py", line 331, in capture_signals
    signal.raise_signal(captured_signal)
  File "C:\Users\User\AppData\Roaming\uv\python\cpython-3.11.13-windows-x86_64-none\Lib\asyncio\runners.py", line 157, in _on_sigint
    raise KeyboardInterrupt()
KeyboardInterrupt

During handling of the above exception, another exception occurred:

Traceback (most recent call last):
  File "C:\Users\User\Desktop\genai-desktop-app\agent\.venv\Lib\site-packages\uvicorn\protocols\http\h11_impl.py", line 403, in run_asgi
    result = await app(  # type: ignore[func-returns-value]
             ^^^^^^^^^^^^^^^^^^^^^^^^^^^^^^^^^^^^^^^^^^^^^^
  File "C:\Users\User\Desktop\genai-desktop-app\agent\.venv\Lib\site-packages\uvicorn\middleware\proxy_headers.py", line 60, in __call__
    return await self.app(scope, receive, send)
           ^^^^^^^^^^^^^^^^^^^^^^^^^^^^^^^^^^^^
  File "C:\Users\User\Desktop\genai-desktop-app\agent\.venv\Lib\site-packages\starlette\applications.py", line 113, in __call__
    await self.middleware_stack(scope, receive, send)
  File "C:\Users\User\Desktop\genai-desktop-app\agent\.venv\Lib\site-packages\starlette\middleware\errors.py", line 164, in __call__
    await self.app(scope, receive, _send)
  File "C:\Users\User\Desktop\genai-desktop-app\agent\.venv\Lib\site-packages\starlette\middleware\exceptions.py", line 63, in __call__
    await wrap_app_handling_exceptions(self.app, conn)(scope, receive, send)
  File "C:\Users\User\Desktop\genai-desktop-app\agent\.venv\Lib\site-packages\starlette\_exception_handler.py", line 42, in wrapped_app
    await app(scope, receive, sender)
  File "C:\Users\User\Desktop\genai-desktop-app\agent\.venv\Lib\site-packages\starlette\routing.py", line 716, in __call__
    await self.middleware_stack(scope, receive, send)
  File "C:\Users\User\Desktop\genai-desktop-app\agent\.venv\Lib\site-packages\starlette\routing.py", line 736, in app
    await route.handle(scope, receive, send)
  File "C:\Users\User\Desktop\genai-desktop-app\agent\.venv\Lib\site-packages\starlette\routing.py", line 290, in handle
    await self.app(scope, receive, send)
  File "C:\Users\User\Desktop\genai-desktop-app\agent\.venv\Lib\site-packages\mcp\server\fastmcp\server.py", line 1045, in __call__
    await self.session_manager.handle_request(scope, receive, send)
  File "C:\Users\User\Desktop\genai-desktop-app\agent\.venv\Lib\site-packages\mcp\server\streamable_http_manager.py", line 144, in handle_request
    await self._handle_stateful_request(scope, receive, send)
  File "C:\Users\User\Desktop\genai-desktop-app\agent\.venv\Lib\site-packages\mcp\server\streamable_http_manager.py", line 216, in _handle_stateful_request
    await transport.handle_request(scope, receive, send)
  File "C:\Users\User\Desktop\genai-desktop-app\agent\.venv\Lib\site-packages\mcp\server\streamable_http.py", line 286, in handle_request
    await self._handle_get_request(request, send)
  File "C:\Users\User\Desktop\genai-desktop-app\agent\.venv\Lib\site-packages\mcp\server\streamable_http.py", line 593, in _handle_get_request
    await response(request.scope, request.receive, send)
  File "C:\Users\User\Desktop\genai-desktop-app\agent\.venv\Lib\site-packages\sse_starlette\sse.py", line 255, in __call__
    async with anyio.create_task_group() as task_group:
  File "C:\Users\User\Desktop\genai-desktop-app\agent\.venv\Lib\site-packages\anyio\_backends\_asyncio.py", line 785, in __aexit__
    raise exc_val
  File "C:\Users\User\Desktop\genai-desktop-app\agent\.venv\Lib\site-packages\anyio\_backends\_asyncio.py", line 753, in __aexit__
    await self._on_completed_fut
asyncio.exceptions.CancelledError
ERROR:    Exception in ASGI application
Traceback (most recent call last):
  File "C:\Users\User\Desktop\genai-desktop-app\agent\.venv\Lib\site-packages\anyio\_backends\_asyncio.py", line 2325, in run
    return runner.run(wrapper())
           ^^^^^^^^^^^^^^^^^^^^^
  File "C:\Users\User\AppData\Roaming\uv\python\cpython-3.11.13-windows-x86_64-none\Lib\asyncio\runners.py", line 118, in run
    return self._loop.run_until_complete(task)
           ^^^^^^^^^^^^^^^^^^^^^^^^^^^^^^^^^^^
  File "C:\Users\User\AppData\Roaming\uv\python\cpython-3.11.13-windows-x86_64-none\Lib\asyncio\base_events.py", line 641, in run_until_complete
    self.run_forever()
  File "C:\Users\User\AppData\Roaming\uv\python\cpython-3.11.13-windows-x86_64-none\Lib\asyncio\windows_events.py", line 321, in run_forever
    super().run_forever()
  File "C:\Users\User\AppData\Roaming\uv\python\cpython-3.11.13-windows-x86_64-none\Lib\asyncio\base_events.py", line 608, in run_forever
    self._run_once()
  File "C:\Users\User\AppData\Roaming\uv\python\cpython-3.11.13-windows-x86_64-none\Lib\asyncio\base_events.py", line 1936, in _run_once
    handle._run()
  File "C:\Users\User\AppData\Roaming\uv\python\cpython-3.11.13-windows-x86_64-none\Lib\asyncio\events.py", line 84, in _run
    self._context.run(self._callback, *self._args)
  File "C:\Users\User\Desktop\genai-desktop-app\agent\.venv\Lib\site-packages\anyio\_backends\_asyncio.py", line 2313, in wrapper
    return await func(*args)
           ^^^^^^^^^^^^^^^^^
  File "C:\Users\User\Desktop\genai-desktop-app\agent\.venv\Lib\site-packages\mcp\server\fastmcp\server.py", line 741, in run_streamable_http_async
    await server.serve()
  File "C:\Users\User\Desktop\genai-desktop-app\agent\.venv\Lib\site-packages\uvicorn\server.py", line 70, in serve
    with self.capture_signals():
  File "C:\Users\User\AppData\Roaming\uv\python\cpython-3.11.13-windows-x86_64-none\Lib\contextlib.py", line 144, in __exit__
    next(self.gen)
  File "C:\Users\User\Desktop\genai-desktop-app\agent\.venv\Lib\site-packages\uvicorn\server.py", line 331, in capture_signals
    signal.raise_signal(captured_signal)
  File "C:\Users\User\AppData\Roaming\uv\python\cpython-3.11.13-windows-x86_64-none\Lib\asyncio\runners.py", line 157, in _on_sigint
    raise KeyboardInterrupt()
KeyboardInterrupt

During handling of the above exception, another exception occurred:

Traceback (most recent call last):
  File "C:\Users\User\Desktop\genai-desktop-app\agent\.venv\Lib\site-packages\uvicorn\protocols\http\h11_impl.py", line 403, in run_asgi
    result = await app(  # type: ignore[func-returns-value]
             ^^^^^^^^^^^^^^^^^^^^^^^^^^^^^^^^^^^^^^^^^^^^^^
  File "C:\Users\User\Desktop\genai-desktop-app\agent\.venv\Lib\site-packages\uvicorn\middleware\proxy_headers.py", line 60, in __call__
    return await self.app(scope, receive, send)
           ^^^^^^^^^^^^^^^^^^^^^^^^^^^^^^^^^^^^
  File "C:\Users\User\Desktop\genai-desktop-app\agent\.venv\Lib\site-packages\starlette\applications.py", line 113, in __call__
    await self.middleware_stack(scope, receive, send)
  File "C:\Users\User\Desktop\genai-desktop-app\agent\.venv\Lib\site-packages\starlette\middleware\errors.py", line 164, in __call__
    await self.app(scope, receive, _send)
  File "C:\Users\User\Desktop\genai-desktop-app\agent\.venv\Lib\site-packages\starlette\middleware\exceptions.py", line 63, in __call__
    await wrap_app_handling_exceptions(self.app, conn)(scope, receive, send)
  File "C:\Users\User\Desktop\genai-desktop-app\agent\.venv\Lib\site-packages\starlette\_exception_handler.py", line 42, in wrapped_app
    await app(scope, receive, sender)
  File "C:\Users\User\Desktop\genai-desktop-app\agent\.venv\Lib\site-packages\starlette\routing.py", line 716, in __call__
    await self.middleware_stack(scope, receive, send)
  File "C:\Users\User\Desktop\genai-desktop-app\agent\.venv\Lib\site-packages\starlette\routing.py", line 736, in app
    await route.handle(scope, receive, send)
  File "C:\Users\User\Desktop\genai-desktop-app\agent\.venv\Lib\site-packages\starlette\routing.py", line 290, in handle
    await self.app(scope, receive, send)
  File "C:\Users\User\Desktop\genai-desktop-app\agent\.venv\Lib\site-packages\mcp\server\fastmcp\server.py", line 1045, in __call__
    await self.session_manager.handle_request(scope, receive, send)
  File "C:\Users\User\Desktop\genai-desktop-app\agent\.venv\Lib\site-packages\mcp\server\streamable_http_manager.py", line 144, in handle_request
    await self._handle_stateful_request(scope, receive, send)
  File "C:\Users\User\Desktop\genai-desktop-app\agent\.venv\Lib\site-packages\mcp\server\streamable_http_manager.py", line 216, in _handle_stateful_request
    await transport.handle_request(scope, receive, send)
  File "C:\Users\User\Desktop\genai-desktop-app\agent\.venv\Lib\site-packages\mcp\server\streamable_http.py", line 286, in handle_request
    await self._handle_get_request(request, send)
  File "C:\Users\User\Desktop\genai-desktop-app\agent\.venv\Lib\site-packages\mcp\server\streamable_http.py", line 593, in _handle_get_request
    await response(request.scope, request.receive, send)
  File "C:\Users\User\Desktop\genai-desktop-app\agent\.venv\Lib\site-packages\sse_starlette\sse.py", line 255, in __call__
    async with anyio.create_task_group() as task_group:
  File "C:\Users\User\Desktop\genai-desktop-app\agent\.venv\Lib\site-packages\anyio\_backends\_asyncio.py", line 785, in __aexit__
    raise exc_val
  File "C:\Users\User\Desktop\genai-desktop-app\agent\.venv\Lib\site-packages\anyio\_backends\_asyncio.py", line 753, in __aexit__
    await self._on_completed_fut
asyncio.exceptions.CancelledError
ERROR:    Traceback (most recent call last):
  File "C:\Users\User\Desktop\genai-desktop-app\agent\.venv\Lib\site-packages\anyio\_backends\_asyncio.py", line 2325, in run
    return runner.run(wrapper())
           ^^^^^^^^^^^^^^^^^^^^^
  File "C:\Users\User\AppData\Roaming\uv\python\cpython-3.11.13-windows-x86_64-none\Lib\asyncio\runners.py", line 118, in run
    return self._loop.run_until_complete(task)
           ^^^^^^^^^^^^^^^^^^^^^^^^^^^^^^^^^^^
  File "C:\Users\User\AppData\Roaming\uv\python\cpython-3.11.13-windows-x86_64-none\Lib\asyncio\base_events.py", line 641, in run_until_complete
    self.run_forever()
  File "C:\Users\User\AppData\Roaming\uv\python\cpython-3.11.13-windows-x86_64-none\Lib\asyncio\windows_events.py", line 321, in run_forever
    super().run_forever()
  File "C:\Users\User\AppData\Roaming\uv\python\cpython-3.11.13-windows-x86_64-none\Lib\asyncio\base_events.py", line 608, in run_forever
    self._run_once()
  File "C:\Users\User\AppData\Roaming\uv\python\cpython-3.11.13-windows-x86_64-none\Lib\asyncio\base_events.py", line 1936, in _run_once
    handle._run()
  File "C:\Users\User\AppData\Roaming\uv\python\cpython-3.11.13-windows-x86_64-none\Lib\asyncio\events.py", line 84, in _run
    self._context.run(self._callback, *self._args)
  File "C:\Users\User\Desktop\genai-desktop-app\agent\.venv\Lib\site-packages\anyio\_backends\_asyncio.py", line 2313, in wrapper
    return await func(*args)
           ^^^^^^^^^^^^^^^^^
  File "C:\Users\User\Desktop\genai-desktop-app\agent\.venv\Lib\site-packages\mcp\server\fastmcp\server.py", line 741, in run_streamable_http_async
    await server.serve()
  File "C:\Users\User\Desktop\genai-desktop-app\agent\.venv\Lib\site-packages\uvicorn\server.py", line 70, in serve
    with self.capture_signals():
  File "C:\Users\User\AppData\Roaming\uv\python\cpython-3.11.13-windows-x86_64-none\Lib\contextlib.py", line 144, in __exit__
    next(self.gen)
  File "C:\Users\User\Desktop\genai-desktop-app\agent\.venv\Lib\site-packages\uvicorn\server.py", line 331, in capture_signals
    signal.raise_signal(captured_signal)
  File "C:\Users\User\AppData\Roaming\uv\python\cpython-3.11.13-windows-x86_64-none\Lib\asyncio\runners.py", line 157, in _on_sigint
    raise KeyboardInterrupt()
KeyboardInterrupt

During handling of the above exception, another exception occurred:

Traceback (most recent call last):
  File "C:\Users\User\Desktop\genai-desktop-app\agent\.venv\Lib\site-packages\starlette\routing.py", line 701, in lifespan
    await receive()
  File "C:\Users\User\Desktop\genai-desktop-app\agent\.venv\Lib\site-packages\uvicorn\lifespan\on.py", line 137, in receive
    return await self.receive_queue.get()
           ^^^^^^^^^^^^^^^^^^^^^^^^^^^^^^
  File "C:\Users\User\AppData\Roaming\uv\python\cpython-3.11.13-windows-x86_64-none\Lib\asyncio\queues.py", line 158, in get
    await getter
asyncio.exceptions.CancelledError

Server shutting down gracefully...
Server has been shut down.
Thank you for using MCP Server!
